{
  "success": false,
  "error": "Traceback (most recent call last):\n  File \"/usr/local/lib/python3.7/dist-packages/crytic_compile/platform/solc.py\", line 242, in get_version\n    process = subprocess.Popen(cmd, stdout=subprocess.PIPE, stderr=subprocess.PIPE)\n  File \"/usr/lib/python3.7/subprocess.py\", line 775, in __init__\n    restore_signals, start_new_session)\n  File \"/usr/lib/python3.7/subprocess.py\", line 1522, in _execute_child\n    raise child_exception_type(errno_num, err_msg, err_filename)\nPermissionError: [Errno 13] Permission denied: 'solc'\n\nDuring handling of the above exception, another exception occurred:\n\nTraceback (most recent call last):\n  File \"/usr/local/lib/python3.7/dist-packages/slither/__main__.py\", line 606, in main_impl\n    printer_classes)\n  File \"/usr/local/lib/python3.7/dist-packages/slither/__main__.py\", line 61, in process_all\n    compilations = compile_all(target, **vars(args))\n  File \"/usr/local/lib/python3.7/dist-packages/crytic_compile/crytic_compile.py\", line 1034, in compile_all\n    compilations.append(CryticCompile(filename, **kwargs))\n  File \"/usr/local/lib/python3.7/dist-packages/crytic_compile/crytic_compile.py\", line 119, in __init__\n    self._compile(**kwargs)\n  File \"/usr/local/lib/python3.7/dist-packages/crytic_compile/crytic_compile.py\", line 924, in _compile\n    self._platform.compile(self, **kwargs)\n  File \"/usr/local/lib/python3.7/dist-packages/crytic_compile/platform/solc.py\", line 106, in compile\n    compiler=\"solc\", version=get_version(solc), optimized=is_optimized(solc_arguments)\n  File \"/usr/local/lib/python3.7/dist-packages/crytic_compile/platform/solc.py\", line 244, in get_version\n    raise InvalidCompilation(error)\ncrytic_compile.platform.exceptions.InvalidCompilation: [Errno 13] Permission denied: 'solc'\n",
  "results": {}
}